# 捕获异常
>time: 2018-03-14 14:34:53

## 1. 捕获异常
如果某个异常发生的时候没有任何地方进行捕获，那程序就会终止执行，并在控制台当打印出异常信息，其中包括异常的类型和堆栈的内容。对于图形界面程序（applet 和应用程序），在捕获异常之后，也会打印出堆桟的信息，但程序将返回到用户界面的处理循环中(在调试 GUI 程序时，最好保证控制台窗口可见，并且没有被最小化）。

捕获一个异常，必须设置 try/catch 语句块。
```java
try {
    code
    more code
    more code
} catch (Exception e) {
    handler for this type
}
```

如果在 try 语句块中的任何代码抛出了一个在 catch 子句中说明的异常类，那么
1. 程序将跳过 try语句块的其余代码。
1. 程序将执行 catch 子句中的处理器代码。

如果在 try 语句块中的代码没有拋出任何异常，那么程序将跳过 catch 子句。  
如果方法中的任何代码拋出了一个在 catch 子句中没有声明的异常类型，那么这个方法就会立刻退出（希望调用者为这种类型的异常设了 catch 子句)。
```java
public void read(String filename) {
    try {
        ImputStream in = new FileInputStream(filename);
        int b;
        while ((b = in.read()) != -1) {
            process input
        } catch (IOException exception) {
            exception.printStackTrace();
        }
    }
}
```

需要注意的是，try 语句中的大多数代码都很容易理解：读取并处理字节，直到遇到文件终止符为止。正如在 Java API 中看到的那样，read  方法有可能抛出一个 IOException 异常。在这种情况下，将跳出整个 while 循环，进入 catch 字句，并生成一个栈轨迹。对于一个普通的程序来说，这样处理异常基本上合乎情理。还有其他的选择吗？  
通常最好的选择是什么也不做，而是将异常传递给调用者。如果 read 方法出现了错误，就让 read 方法的调用者去操心！如果采用这种处理方式，就必须声明这个方法可能抛出一个 IOException。
```java
public void read(String  filename) throws IOException {
    InputStream in = new FileInputStream(filename);
    int b;
    while ((b = in.read()) != -1) {
        process input
    }
}
```
请记住，编译器严格地执行 throws 说明符。如果调用了一个抛出受查异常的方法，就必须对它进行处理，或者继续传递。  
哪种方法更好呢？通常，应该捕获那些知道如何处理的异常，而将那些不知道怎样处理的异常继续进行传递。  
如果想传递一个异常，就必须在方法的首部添加一个 throws 说明符，以便告知调用者这个方法可能会抛出异常。

仔细阅读一下 Java API 文档，以便知道每个方法可能会抛出哪种异常，然后再决定是自己处理，还是添加到 throws 列表中。对于后一种情况，也不必犹豫。将异常直接交给能胜任的处理器进行处理要比压制对它的处理更好。

同时请记住，这个规则也有一个例外，前面曾经提到过： 如果编写一个覆盖超类的方法，而这个方法有没有抛出异常（如 JComponent 中的 paintComponent），那么这个方法就必须捕获方法代码中出现的每一个受查异常。不允许在子类的 throws 说明符中出现超类方法所列出的异常类范围。

## 2. 捕获多个异常
在一个 try 语句块中可以捕获多个异常类型，并对不同类型的异常做出不同的处理。可以按照下列方式为每个异常类型使用一个单独的 catch 子句：
```java
try {
    code that might throw exceptions
} catch (FileNotFoundException e) {
    emergency action for missing files
} catch (UnknownHostException e) {
    emergency action for unknown hosts
} catch (IOException e) {
    emergency action for all other I/O problems
}
```
异常对象可能包含与异常本身有关的信息。要想获得对象的更多信息，可以试着使用  
`e.getMessage()`  
得到详细的错误信息（如果有的话），或者使用  
`e.getClass().getName()`  
得到异常对象的实际类型。

在 Java SE 7 中，同一个 catch 子句中可以捕获多个异常类型。
```java
try {
    code that might throw exception
} catch(FileNotFoundException | UnknownHostException e) {
    emergency action for missing files and unknown hosts
} catch(IOException e) {
    emergency action for all other I/O problems
}
```
只有当捕获的异常类型彼此之间不存在子类关系时才需要这个特性。

**注释**： 捕获多个异常时，异常变量隐含为 final 变量。例如，不能再一下子句中为 e 赋不同的值：  
`catch (FileNotFoundException | UnknowHostException e) {...}`

**注释**： 捕获多个异常不仅会让你的代码看起来更简单，还会更高效。生成的字节码只包含一个对应公共 catch 子句的代码块。

## 3. 再次抛出异常与异常链

在 catch 子句中可以抛出一个异常，这样做的目的是改变异常的类型。如果开发了一个供其他程序员使用了子系统，那么，用于表示子系统故障的异常类型可能会产生多种解释。ServletException 就是这样一个异常类型的例子。执行 servlet 的代码可能不想知道发生错误的细节原因，但希望明确地知道 servlet 是否有问题。  
捕获异常并将它再次抛出的基本方法：
```java
try {
    access the database
} catch(SQLException e) {
    throw new ServletException("database error: " + e.getMessage());
}
```
这里，ServleException 用带有异常信息文本的构造器来构造。  
不过，可以有一种更好的处理方法，并且将原始异常设置为新异常的“原因”：  
```java
try{
    access the database
} catch (SQLException e) {
    Throwable se = new ServletException("database error");
    se.initCause(e);
    throw se;
}
```
当捕获到异常时， 就可以使用下面这条语句重新得到原始异常：  
`Throwable e = se.getCause();`  
强烈建议使用这种包装技术。这样可以让用户抛出子系统中的高级异常，而不会丢失原始异常的细节。

**提示**： 如果在一个方法中发生了一个受查异常，而不允许抛出它，那么包装技术就十分有用。我们可以捕获这个受查异常， 并将它包装成一个运行时异常。

有时你可能只想记录一个异常， 再将它重新抛出， 而不做任何改变：
```java
try {
    access the database
} catch(Exception e) {
    logger.log(level, message, e);
    throw e;
}
```
在 Java SE 7 之前，这种方法存在一个问题。假设这个代码在以下方法中：  
`public void updateRecord() throws SQLException`  
Java 编译器查看 catch 块中的 throw 语句，然后查看 e 的类型，会指出这个方法可以抛出任何 Exception 而不只是 SQLException。现在这个问题已经有所改进。编译器会跟踪到 e 来自 try 块。假设这个 try 块中仅有的已检查异常是 SQLException 实例，另外，假设 e 在 catch 块中未改变，将外围方法声明为 throws SQLException 就是合法的。

## 4. finally 子句
当代码抛出一个异常时， 就会终止方法中剩余代码的处理，并退出这个方法的执行。 如果方法获得了一些本地资源，并且只有这个方法自己知道，又如果这些资源在退出方法之前必须被回收，那么就会产生资源回收问题。一种解决方案是捕获并重新抛出所有的异常。但是，这种解决方案比较乏味，这是因为需要在两个地方清除所分配的资源。一个在正常的代码中；另一个在异常代码中。Java有一种更好的解决方案，这就是 finally 子句。

不管是否有异常被捕获， finally 子句中的代码都被执行。
```java
InputStream in = new FileInputStream(...);
try {
    // 1
    code that might throw exception
    // 2
} catch (IOException e) {
    //  3
    show error message
    // 4
} finally {
    // 5
    in.close();
}
// 6
```
在上面这段代码中，有下列 3 种情况会执行 finally 子句：
1. 代码没有抛出异常。在这种情况下，程序首先执行 try 语句块中的全部代码，然后执 finally 子句中的代码。随后，继续执行 try 语句块之后的第一条语句。也就是说，执行标注的 1、 2、 5、 6 处。

2. 抛出一个在 catch 子句中捕获的异常。在上面的示例中就是 IOException 异常。在这种情况下，程序将执行 try 语句块中的所有代码，直到发生异常为止。此时，将跳过 try 语句块中的剩余代码，转去执行与该异常匹配的 catch 子句中的代码，最后执行 finally 子句中的代码。
    1. 如果 catch子句没有抛出异常，程序将执行 try 语句块之后的第一条语句。在这里，执行标注 1、 3、 4、5、 6处的语句。
    1. 如果 catch 子句抛出了一个异常，异常将被抛回这个方法的调用者。在这里， 执行标注 1、3、5 处的语句。

1. 代码抛出了一个异常，但这个异常不是由 catch 子句捕获的。在这种情况下，程序将执行 try 语句块中的所有语句，直到有异常被抛出为止。此时，将跳过 try 语句块中的剩余代码，然后执行 finally 子句中的语句，并将异常抛给这个方法的调用者。在这里，执行标注 1、5 处的语句。

```java
InputStream in = ...;
try {
    code that might throw exception
} finally {
    in.close();
}
```
无论在 try 语句块中是否遇到异常， finally 子句中的 in.close() 语句都会被执行。当然，如果真的遇到一个异常，这个异常将会被重新抛出，并且必须由另一个 catch 子句捕获。  
事实上， 我们认为在需要关闭资源时， 用这种方式使用 finally 子句是一种不错的选择。

***
**提示**： 这里，强烈建议解搞合 try/catch 和 try/finally 语句块。 这样可以提高代码的清晰度。例如：
```java
InputStream in = ...;
try {
    try {
        code that might throw exception
    } finally {
        in.close();
    }
} catch (IOException e) {
    show error message
}
```
内层的 try 语句块只有一个职责，就是确保关闭输入流。 外层的 try 语句块也只有一个职责，就是确保报告出现的错误。这种设计方式不仅清楚，而且还具有一个功能，就是将会报告 finally 子句中出现的错误。
***

***
**警告**： 当 finally 子句包含 return 语句时，将会出现一种意想不到的结果。假设利用 return 语句从 try 语句块中退出。在方法返回前，finally 子句的内容将被执行。如果 finally 子句中也有一个 return 语句， 这个返回值将会覆盖原始的返回值。请看一个复杂的例子：
```java
public static int f(int n) {
    try {
        int r = n * n;
        return r;
    } finally {
        if (n ==2) return 0;
    }
}
```
如果调用 f(2)，那么 try 语句块的计算结果为 r = 4，并执行 return 语句。然而，在方法真正返回前，还要执行 finally 子句。finally 子句将使得方法返回 0，这个返回值覆盖了原始的返回值 4。
***

有时候，finally 子句也会带来麻烦。例如，清理资源的方法也有可能抛出异常。假设希望能够确保在流处理代码中遇到异常时将流关闭。
```java
InputStream in = ...;
try {
    code that might throw exceptions
} finally {
    in.close();
}
```

现在，假设在 try 语句块中的代码抛出了一些非 IOException 的异常，这些异常只有这个方法的调用者才能够给予处理。执行 finally 语句块，并调用 close 方法。而 close 方法本身有可能抛出 IOException 异常。当出现这种情况时，原始的异常将会丢失，转而抛出 close 方法的异常。  
这会有问题，因为第一个异常很可能更有意思。如果你想做适当的处理， 重新抛出原来的异常，代码会变得极其繁琐。
```java
InputStream in = ...;
Exception ex = null;
try {
    try {
        code that might throw exception
    } catch (Exception e) {
        ex = e;
        throw e;
    }
}finally {
    try {
        in.close();
    } catch (Exception e) {
        if (ex == null) {
            thtow e;
        }
    }
}
```

## 5. 代资源的 try 语句
```java
open a resource
try {
    work with the resource
} finally {
    close the resource
}
```

假设资源属于一个实现了 AutoCloseable 接口的类， Java SE 7 为这种代码提供了一个很有用的快捷方式。AutoCloseable 接口有一个方法：  
`void close() trhrow Exception`

**注释**：另外，还有一个 Closeable 接口。这是 AutoCloseable 的子接口，也包含一个 close 方法。不过，这个方法声明为抛出一个 IOException。

带资源的 try 语句（try-with-resource） 的最简形式为：
```java
try (Resource res = ...) {
    wokr with res
}
```

try 块退出时，会自动调用 res.dose()。读取一个文件内所有单词的例子：
```java
try(Scanner in = new Scanner(new FileInputStream("/usr/share/dict/words"), "UTF-8")) {
    while(in.hasNext()) {
        System.out.println(in.next());
    }
}
```
这个块正常退出时，或者存在一个异常时，都会调用 inxloseO方法，就好像使用了finally 块一样。还可以指定多个资源：
```java
try(Scanner in = new Scanner(new FileInputStream("/usr/share/dict/words"), "UTF-8");
        PrintWriter out = new PrintWriter("out.txt")) {
    while(in.hasNext()) {
        out.println(in.next());
    }
} catch (FileNotFoundException e) {
    // TODO Auto-generated catch block
    e.printStackTrace();
}
```
不论这个块如何退出，in 和 out 都会关闭。如果你用常规方式手动编程，就需要两个嵌套的 try/finally 语句。

如果 try 块抛出一个异常， 而且 close 方法也抛出一个异常，这就会带来一个难题。带资源的 try 语句可以很好地处理这种情况。原来的异常会重新抛出，而 close 方法抛出的异常会“被抑制”。这些异常将自动捕获，并由 addSuppressed 方法增加到原来的异常。如果对这些异常感兴趣，可以调用 getSuppressed 方法，它会得到从 close 方法抛出并被抑制的异常列表。

你肯定不想采用这种常规方式编程。只要需要关闭资源，就要尽可能使用带资源的 try 语句。

***
**注释**：带资源的 try 语句自身也可以有 catch 子句和一个 finally 子句。 这些子句会在关闭资源之后执行。 不过在实际中， 一个 try 语句中加入这么多内容可能不是一个好主意。
***

## 6. 分析堆栈轨迹元素

**堆栈轨迹（stack trace）** 是一个方法调用过程的列表，它包含了程序执行过程中方法调用的特定位置。前面已经看到这种列表，当 Java 程序正常终止，而没有捕获异常时，这个列表就会显示出来。

可以调用 Throwable 类的 printStackTrace 方法访问堆栈轨迹的文本描述信息。
```java
Throwable t = new Throwable();
StringWriter out = new StringWriter();
t.printStackTrace(new PrintWriter(out));
String description = out.toString();
```
一种更灵活的方法是使用 getStackTrace 方法，它会得到 StackTraceElement 对象的一个数组，可以在你的程序中分析这个对象数组。
```java
Throwable t = new Throwable();
StackTraceElement[] frames = t.getStackTrace();
for(StackTraceElement frame : frames) {
    analyze frame
}
```

StackTraceElement 类含有能够获得文件名和当前执行的代码行号的方法，同时，还含有能够获得类名和方法名的方法。toString 方法将产生一个格式化的字符串，其中包含所获得的信息。

静态的 Thread.getAllStackTrace 方法，它可以产生所有线程的堆栈轨迹。
```java
Map<Thread, StackTraceElement[]> map = Thread.getAllStackTraces();
for (Thread t : map.keySet()) {
    StackTraceElement[] frames = map.get(t);
    // analyze frames
}
```


```java
import java.util.*;

public class StackTraceTest {

    public static int factorial(int n) {
        System.out.println("factorial(" + n + "):");
        Throwable t = new Throwable();
        StackTraceElement[] frames = t.getStackTrace();
        for (StackTraceElement f : frames) {
            System.out.println(f);
        }
        int r;
        if ( n <= 1) {
            r = 1;
        }else {
            r = n * factorial(n - 1);
        }
        System.out.println("return " + r);
        return r;
    }
    public static void main(String[] args) {
        Scanner in = new Scanner(System.in);
        System.out.print("Enter n: ");
        int n = in.nextInt();
        factorial(n);
    }

}
```
输出：
```
Enter n: 3
factorial(3):
core.StackTraceTest.factorial(StackTraceTest.java:9)
core.StackTraceTest.main(StackTraceTest.java:27)
factorial(2):
core.StackTraceTest.factorial(StackTraceTest.java:9)
core.StackTraceTest.factorial(StackTraceTest.java:18)
core.StackTraceTest.main(StackTraceTest.java:27)
factorial(1):
core.StackTraceTest.factorial(StackTraceTest.java:9)
core.StackTraceTest.factorial(StackTraceTest.java:18)
core.StackTraceTest.factorial(StackTraceTest.java:18)
core.StackTraceTest.main(StackTraceTest.java:27)
return 1
return 2
return 6
```

#### java.lang.Throwable 1.0
* Throwable(Throwable cause) 1.4
* Throwable(String message, Throwable cause) 1.4
    >用给定的“原因”构造一个 Throwable 对象。
* Throwable initCause(Throwable cause) 1.4
    >将这个对象设置为“原因”。如果这个对象已经被设置为“原因”，则抛出一个异常。返回 this 引用。
* Throwable getCause() 1.4
    >获得设置为这个对象的“原因”的异常对象。如果没有设置“原因”，则返回 null。
* StackTraceElement[] getStackTrace() 1.4
    >获得构造这个对象时调用堆栈的跟踪。
* void addSuppressed(Throwable t) 7
    >为这个异常增加一个“抑制”异常。这出现在带资源的 try 语句中，其中 t 是 close 方法抛出的一个异常。
* Throwable[] getSuppressed() 7
    >得到这个异常的所有“抑制”异常。一般来说，这些带资源的 try 语句中的 close 方法抛出的异常。

#### java.lang.Exception 1.0
* Exception(Throwable cause) 1.4
* Exception(String message, Throwable cause)
    >用给定的“原因”构造一个异常对象象。

####  java.lang.RuntimeException 1.0
* RuntimeException(Throwable cause) 1.4
* RuntimeException(String message, Throwable cause) 1.4
    >用给定的“原因”构造一个 RuntimeException对象。

####  java.lang.StackTraceElement 1.4
*  java.lang.StackTraceElement 1.4
    >返回这个元素运行时对应的源文件名。如果这信息不存在，则返回 null。
* int getLineNumber()
    >返回这个元素运行时对应的源文件行数。如果这个信息不存在，则返回 -1。
* String getClassName()
    >返回这个元素运行时对应的类的完全限定名。
* String getMethodName()
    >返回这个元素运行时对应的方法名。构造器名是`<init>`;静态初始化器名是 `<clinit>`。这里无法区分同名的重载方法。
* boolean isNativeMethod()
    >如果这个元素运行时在一个本地方法中，则返回 true。
* String toString()
    >如果存在的话，返回一个包含类名、方法名、文件名和行数的格式化字符串。